Workbook
Name Text2: '3. 驗收單'!#REF!
Name Text3: '3. 驗收單'!#REF!
Name Text4: '3. 驗收單'!#REF!
Name weekday_option: MATCH(開始日,'4. 費用申請單'!工作日_反轉,0)-2
Name weekday_option: MATCH(開始日,各項支出報支規定!工作日_反轉,0)-2
Name 工作日: {"星期一","星期二","星期三","星期四","星期五","星期六","星期日"}
Name 工作日: {"星期一","星期二","星期三","星期四","星期五","星期六","星期日"}
Name 工作日: {"星期一","星期二","星期三","星期四","星期五","星期六","星期日"}
Name 工作日_反轉: {"星期日","星期六","星期五","星期四","星期三","星期二","星期一"}
Name 工作日_反轉: {"星期日","星期六","星期五","星期四","星期三","星期二","星期一"}
Name 日: {0,1,2,3,4,5,6}
Name 日: {0,1,2,3,4,5,6}
Name 日格線: '4. 費用申請單'!日+'4. 費用申請單'!週*7
Name 日格線: 各項支出報支規定!日+各項支出報支規定!週*7
Name 日圖樣: {1,1,2,2,3,3,4,4,5,5,6,6,7}
Name 日圖樣: {1,1,2,2,3,3,4,4,5,5,6,6,7}
Name 月份: {"一月","二月","三月","四月","五月","六月","七月","八月","九月","十月","十一月","十二月"}
Name 月份: {"一月","二月","三月","四月","五月","六月","七月","八月","九月","十月","十一月","十二月"}
Name 月份: {"一月","二月","三月","四月","五月","六月","七月","八月","九月","十月","十一月","十二月"}
Name 週: {0;1;2;3;4;5;6}
Name 週: {0;1;2;3;4;5;6}

Sheet 請先閱讀
A1: 台灣智慧駕駛股份有限公司
A2: 採購流程圖
B3: 情況一：符合以下兩條件可委由管理部進行採購單申請、費用申請以及廠商聯繫等作業 條件1. 同廠商、同品項 條件2. 第二次採購 需求單位應執行表單(藍底表單)：請購單、採購選手清單、客供資料卡、驗收單 管理部應執行表單(綠底表單)：採購單、費用申請單(管理部會根據採購選手清單向廠商取得報價單進行後續採購直到出貨) 情況二：若不符合以上條件，需求單位應自行完成全部流程 需求單位應執行表單(藍底表單)：請購單、採購單、費用申請單、驗收單 | X3: Step1. 在一切開始之前，請先判斷本次費用是否需要走採購程序，可參考「各項支出報支規定」 採購程序包含: 請購、採購、驗收、費用申請 非採購程序者，僅需費用申請
X6: Step2.請購單
X7: 請購步驟及注意事項
X8: 1. 選取預算來源跟項目後會自動帶出預算編號，若無，請走預算新增流程
X9: 2. 請購單號找總務索取
X10: 3.請申請人填寫工號後確認部門等簽核資訊是否正確
X11: 4. 預計需求天數為這個採購需要幾天內完成(到貨)，會自動推算出日期
X12: 5. 同一預算來源且同一供應商者可合併請購
X16: Step3.採購單
X17: 採購步驟及注意事項_x000B_
X18: 1. 請購完成後才可啟動採購
X19: 2.採購單號由請購單自動帶出
X20: 3. 採購廠商需手動填寫
... X51: 2.以上每個申請單皆需簽核完成，始得下個申請單流程開始

Sheet 各項支出報支規定
B1: 項目彙總 | C1: 參考案例 | D1: 支出報支規定 | E1: 使用表單
B2: 人事費(薪資、退休金) | C2: 常態薪資、臨時人力 | D2: 薪工循環 | E2: 人力需求申請單
B3: 訓練費 | C3: 教育訓練費 | E3: 教育訓練申請單、教育訓練報告單、費用申請單
B4: 租金支出 | C4: 辦公室租金 | D4: 單筆10,001以上=>採購流程→ 單筆10,000以下=>費用報支流程→ | E4: 請購申請單、採購申請單、驗收單、費用申請單 費用申請單
B5: 廣告費 | C5: 廣宣費用
B6: 勞務費 | C6: 委外勞務
B7: 保險費 | C7: 團保、火險、公共意外責任險
B8: 開發費 | C8: 委外開發
B9: 郵電費 | C9: SIM卡費用、電話費、郵票
B10: 材料 | C10: 耗材、材料
B11: 設備 | C11: 設備購置
B12: 雜費 | C12: 雜費
B13: 運費 | C13: 運費
B14: 設備維護費 | C14: 設備保養費
B15: 交際費 | C15: 交際費 | D15: 費用報支流程 | E15: 費用申請單
B16: 職工福利 | C16: 部門聚餐
B19: 注意事項：（採購請款流程時常見錯誤）
B20: 1. 請購申請單中的請購單號需向財會取號。
B21: 2. 如為國內廠商以外幣進行報價及收付款，請確定交易金額是否需含本國營業稅5%及該交易憑證開立方式。
B22: 3. 如採購金額超過3萬以上，或經常性每年採購6次以上之供應商，需請對方填寫「供應商基本資料卡」，並請申請人確認。
B23: 4. 廠商報價單上的付款條件，需能對應到該費用申請單的期望付款日。（舉例說明：假設廠商報價單寫月結30日，但是申請人已寫費用申請單申請預付，是不符合本次採購付款條件，將會退回費用申請單。）
B24: 5. 發票和免用統一發票收據的總計中文大寫處誤寫成阿拉伯數字，請寫”零壹貳參肆伍陸柒捌玖”。
B25: 6. 國內廠商之報價單、發票或收據的買受人必需為「台灣智慧駕駛股份有限公司」，國外廠商之QUOTATION、INVOICE或RECEIPT的買受人必需為「TURING DRIVE INC.」。
B26: 7. 交際費請款必需寫上宴請對象。
B27: 8. 申請之費用如有使用期間（如：軟體帳號使用期間及訂閱期間…等），請在費用申請單上註明。
B28: 9. 如期望付款日未明確填寫日期，將會以月結30天方式安排付款（即廠商開立發票月份的次月30號付款）。
B29: 10. 請購、採購及驗收請款流程請確實按照公司採購流程進行，勿將所有文件同時送簽。

Sheet link
A1: 序號 | B1: 員工代號(ERP) | C1: 員工姓名 | D1: 部門 | E1: 部門代碼 | F1: 部門主管 | G1: 職稱 | H1: 核准 | J1: 付款方式 | L1: 付款條件 | N1: 請購單次序 | P1: 採購單次序 | R1: 部門 | S1: 部門代號 | T1: 大項分類 | U1: 部門/專案 | V1: 中項分類 | W1: 預算編號(*)： | X1: 項目彙總 | Y1: 115年合計 | Z1: 合併欄位 | AA1: 預算 | AC1: 部門 | AD1: 代號 | AE1: 主管 | AG1: 中項分類 | AI1: --------部門---------
A2: =ROW()-1 -> 1 | B2: 0001 | C2: 陳維隆 | D2: 董事長室 | E2: CO | F2: 陳維隆 | G2: 董事長 | H2: 沈大維 | J2: 支票 | L2: 預付 | N2: A1 | P2: B1 | R2: 管理部 | S2: AD | T2: 營業費用 | U2: =S2&R2 -> AD管理部 | V2: 人事費 | W2: 115ADSE01 | X2: 人事費(薪資、各項獎金) | Y2: -4063966 | Z2: =U2&X2 -> AD管理部人事費(薪資、各項獎金) | AA2: =IF(OR(X2="旅費", X2="折舊及攤銷"), "無預算", IF(AND(ISNUMBER(Y2), Y2<>0), W2, "無預算")) -> 115ADSE01 | AC2: 管理部 | AD2: AD | AE2: 吳旭東 | AG2: -----部門----- | AI2: =AC2 -> 管理部
A3: =ROW()-1 -> 2 | B3: 0002 | C3: 沈大維 | D3: 總經理室 | E3: GO | F3: 沈大維 | G3: 執行長 | H3: 陳維隆 | J3: 匯款 | L3: 當月底付款 | N3: A2 | P3: B2 | R3: 管理部 | S3: AD | T3: 營業費用 | U3: =S3&R3 -> AD管理部 | V3: 租金支出 | W3: 115ADSE02 | X3: 租金支出 | Y3: -1002000 | Z3: =U3&X3 -> AD管理部租金支出 | AA3: =IF(OR(X3="旅費", X3="折舊及攤銷"), "無預算", IF(AND(ISNUMBER(Y3), Y3<>0), W3, "無預算")) -> 115ADSE02 | AC3: 自動駕駛系統部 | AD3: ADS | AE3: 楊為任 | AG3: 人事費(薪資、各項獎金) | AI3: =AC3 -> 自動駕駛系統部
A4: =ROW()-1 -> 3 | B4: 0009 | C4: 許雲茹 | D4: 管理部 | E4: AD | F4: 吳旭東 | G4: 行政財會 | H4: 沈大維 | J4: 現鈔 | L4: 月結30天 | N4: A3 | P4: B3 | R4: 管理部 | S4: AD | T4: 營業費用 | U4: =S4&R4 -> AD管理部 | V4: 旅費 | W4: 115ADSE03 | X4: 旅費 | Y4: 0 | Z4: =U4&X4 -> AD管理部旅費 | AA4: =IF(OR(X4="旅費", X4="折舊及攤銷"), "無預算", IF(AND(ISNUMBER(Y4), Y4<>0), W4, "無預算")) -> 無預算 | AC4: 營業行銷部 | AD4: S&M | AE4: 陳維隆 | AG4: 租金支出 | AI4: =AC4 -> 營業行銷部
A5: =ROW()-1 -> 4 | B5: 0017 | C5: 阮振瑋 | D5: 自動駕駛系統部 | E5: ADS | F5: 楊為任 | G5: 工程經理 | H5: 沈大維 | J5: 繳費 | L5: 月結60天 | N5: A4 | P5: B4 | R5: 管理部 | S5: AD | T5: 營業費用 | U5: =S5&R5 -> AD管理部 | V5: 運費 | W5: 115ADSE04 | X5: 運費 | Y5: -3600 | Z5: =U5&X5 -> AD管理部運費 | AA5: =IF(OR(X5="旅費", X5="折舊及攤銷"), "無預算", IF(AND(ISNUMBER(Y5), Y5<>0), W5, "無預算")) -> 115ADSE04 | AC5: 董事長室 | AD5: CO | AE5: 陳維隆 | AG5: 運費 | AI5: =AC5 -> 董事長室
A6: =ROW()-1 -> 5 | B6: 0019 | C6: 呂京霖 | D6: 自動駕駛系統部 | E6: ADS | F6: 楊為任 | G6: 主任工程師 | H6: 沈大維 | J6: 外匯 | L6: 月結90天 | N6: A5 | P6: B5 | R6: 管理部 | S6: AD | T6: 營業費用 | U6: =S6&R6 -> AD管理部 | V6: 郵電費 | W6: 115ADSE05 | X6: 郵電費 | Y6: -42000 | Z6: =U6&X6 -> AD管理部郵電費 | AA6: =IF(OR(X6="旅費", X6="折舊及攤銷"), "無預算", IF(AND(ISNUMBER(Y6), Y6<>0), W6, "無預算")) -> 115ADSE05 | AC6: 總經理室 | AD6: GO | AE6: 沈大維 | AG6: 郵電費 | AI6: =AC6 -> 總經理室
A7: =ROW()-1 -> 6 | B7: 0020 | C7: 何宗璟 | D7: 自動駕駛系統部 | E7: ADS | F7: 楊為任 | G7: 工程師 | H7: 沈大維 | J7: 零用金 | N7: A6 | P7: B6 | R7: 管理部 | S7: AD | T7: 營業費用 | U7: =S7&R7 -> AD管理部 | V7: 修繕費 | W7: 115ADSE06 | X7: 修繕費 | Y7: 0 | Z7: =U7&X7 -> AD管理部修繕費 | AA7: =IF(OR(X7="旅費", X7="折舊及攤銷"), "無預算", IF(AND(ISNUMBER(Y7), Y7<>0), W7, "無預算")) -> 無預算 | AC7: 資料與雲端平台部 | AD7: D&C | AE7: 楊為任 | AG7: 修繕費 | AI7: =AC7 -> 資料與雲端平台部
A8: =ROW()-1 -> 7 | B8: 0023 | C8: 李嘉偉 | D8: 自動駕駛系統部 | E8: ADS | F8: 楊為任 | G8: 資深工程師 | H8: 沈大維 | J8: 其他 | N8: A7 | P8: B7 | R8: 管理部 | S8: AD | T8: 營業費用 | U8: =S8&R8 -> AD管理部 | V8: 廣告費 | W8: 115ADSE07 | X8: 廣告費 | Y8: 0 | Z8: =U8&X8 -> AD管理部廣告費 | AA8: =IF(OR(X8="旅費", X8="折舊及攤銷"), "無預算", IF(AND(ISNUMBER(Y8), Y8<>0), W8, "無預算")) -> 無預算 | AC8: 產品部 | AD8: PD | AE8: 沈大維 | AG8: 廣告費 | AI8: =AC8 -> 產品部
A9: =ROW()-1 -> 8 | B9: 0025 | C9: 王冠傑 | D9: 自動駕駛系統部 | E9: ADS | F9: 楊為任 | G9: 資深工程師 | H9: 沈大維 | N9: A8 | P9: B8 | R9: 管理部 | S9: AD | T9: 營業費用 | U9: =S9&R9 -> AD管理部 | V9: 保險費 | W9: 115ADSE08 | X9: 保險費 | Y9: -572072 | Z9: =U9&X9 -> AD管理部保險費 | AA9: =IF(OR(X9="旅費", X9="折舊及攤銷"), "無預算", IF(AND(ISNUMBER(Y9), Y9<>0), W9, "無預算")) -> 115ADSE08 | AC9: 車輛開發部 | AD9: VD | AE9: 陳冠文 | AG9: 保險費 | AI9: =AC9 -> 車輛開發部
A10: =ROW()-1 -> 9 | B10: 0032 | C10: 陳冠文 | D10: 車輛開發部 | E10: VD | F10: 陳冠文 | G10: 副總經理 | H10: 沈大維 | N10: A9 | P10: B9 | R10: 管理部 | S10: AD | T10: 營業費用 | U10: =S10&R10 -> AD管理部 | V10: 交際費 | W10: 115ADSE09 | X10: 交際費 | Y10: -6000 | Z10: =U10&X10 -> AD管理部交際費 | AA10: =IF(OR(X10="旅費", X10="折舊及攤銷"), "無預算", IF(AND(ISNUMBER(Y10), Y10<>0), W10, "無預算")) -> 115ADSE09 | AC10: 亞灣2.0:5G a lot規模化加值感育樂服務創新應用計畫 | AD10: 112BD003 | AE10: 劉君怡 | AG10: 交際費 | AI10: --------專案---------
A11: =ROW()-1 -> 10 | B11: 0046 | C11: 賴昭宇 | D11: 車輛開發部 | E11: VD | F11: 陳冠文 | G11: 資深車輛開發工程師 | H11: 沈大維 | N11: A10 | P11: B10 | R11: 管理部 | S11: AD | T11: 營業費用 | U11: =S11&R11 -> AD管理部 | V11: 折舊及攤銷 | W11: 115ADSE10 | X11: 折舊及攤銷 | Y11: -54144 | Z11: =U11&X11 -> AD管理部折舊及攤銷 | AA11: =IF(OR(X11="旅費", X11="折舊及攤銷"), "無預算", IF(AND(ISNUMBER(Y11), Y11<>0), W11, "無預算")) -> 無預算 | AC11: 雲科大教具車案(翔和) | AD11: 113BD005 | AE11: 劉君怡 | AG11: 職工福利 | AI11: =AC10 -> 亞灣2.0:5G a lot規模化加值感育樂服務創新應用計畫
A12: =ROW()-1 -> 11 | B12: 0052 | C12: 莊育俊 | D12: 產品部 | E12: PD | F12: 沈大維 | G12: 資深產品經理 | H12: 沈大維 | N12: A11 | P12: B11 | R12: 管理部 | S12: AD | T12: 營業費用 | U12: =S12&R12 -> AD管理部 | V12: 職工福利 | W12: 115ADSE11 | X12: 職工福利 | Y12: -263000 | Z12: =U12&X12 -> AD管理部職工福利 | AA12: =IF(OR(X12="旅費", X12="折舊及攤銷"), "無預算", IF(AND(ISNUMBER(Y12), Y12<>0), W12, "無預算")) -> 115ADSE11 | AC12: 宮古島郵輪航廈至海灘一般道路接駁實驗 | AD12: 114BD012 | AE12: 熊可晴 | AG12: 訓練費 | AI12: =AC11 -> 雲科大教具車案(翔和)
A13: =ROW()-1 -> 12 | B13: 0053 | C13: 楊為任 | D13: 自動駕駛系統部 | E13: ADS | F13: 楊為任 | G13: 軟體研發副總 | H13: 沈大維 | N13: A12 | P13: B12 | R13: 管理部 | S13: AD | T13: 營業費用 | U13: =S13&R13 -> AD管理部 | V13: 訓練費 | W13: 115ADSE12 | X13: 訓練費 | Y13: -30000 | Z13: =U13&X13 -> AD管理部訓練費 | AA13: =IF(OR(X13="旅費", X13="折舊及攤銷"), "無預算", IF(AND(ISNUMBER(Y13), Y13<>0), W13, "無預算")) -> 115ADSE12 | AC13: 臺大教具車 | AD13: 114BD014 | AE13: 莊育俊 | AG13: 開發費 | AI13: =AC12 -> 宮古島郵輪航廈至海灘一般道路接駁實驗
A14: =ROW()-1 -> 13 | B14: 0054 | C14: 呂孟耿 | D14: 總經理室 | E14: GO | F14: 沈大維 | G14: 副總經理 | H14: 沈大維 | N14: A13 | P14: B13 | R14: 管理部 | S14: AD | T14: 營業費用 | U14: =S14&R14 -> AD管理部 | V14: 開發費 | W14: 115ADSE13 | X14: =V14 -> 開發費 | Y14: 0 | Z14: =U14&X14 -> AD管理部開發費 | AA14: =IF(OR(X14="旅費", X14="折舊及攤銷"), "無預算", IF(AND(ISNUMBER(Y14), Y14<>0), W14, "無預算")) -> 無預算 | AC14: 7STARLAKE自動駕駛巡邏車與派遣車開發 | AD14: 115BD001 | AE14: 莊育俊 | AG14: 勞務費 | AI14: =AC13 -> 臺大教具車
A15: =ROW()-1 -> 14 | B15: 0056 | C15: 莊朝淵 | D15: 車輛開發部 | E15: VD | F15: 陳冠文 | G15: 資深電子電機工程師 | H15: 沈大維 | N15: A14 | P15: B14 | R15: 管理部 | S15: AD | T15: 營業費用 | U15: =S15&R15 -> AD管理部 | V15: 勞務費 | W15: 115ADSE14 | X15: 勞務費 | Y15: -630000 | Z15: =U15&V15 -> AD管理部勞務費 | AA15: =IF(OR(X15="旅費", X15="折舊及攤銷"), "無預算", IF(AND(ISNUMBER(Y15), Y15<>0), W15, "無預算")) -> 115ADSE14 | AC15: NSC: remote support | AD15: 115BD002 | AE15: 熊可晴 | AG15: 交通費 | AI15: =AC14 -> 7STARLAKE自動駕駛巡邏車與派遣車開發
A16: =ROW()-1 -> 15 | B16: 0060 | C16: 張晏銘 | D16: 產品部 | E16: PD | F16: 沈大維 | G16: 產品經理 | H16: 沈大維 | R16: 管理部 | S16: AD | T16: 營業費用 | U16: =S16&R16 -> AD管理部 | V16: 交通費 | W16: 115ADSE15 | X16: 交通費 | Y16: -14400 | Z16: =U16&V16 -> AD管理部交通費 | AA16: =IF(OR(X16="旅費", X16="折舊及攤銷"), "無預算", IF(AND(ISNUMBER(Y16), Y16<>0), W16, "無預算")) -> 115ADSE15 | AC16: 臺灣桃園國際機場第三航站區旅客運輸系統工程-建置車輛監控管理系統 | AD16: 115BD004 | AE16: 呂孟耿 | AG16: 設備 | AI16: =AC15 -> NSC: remote support
A17: =ROW()-1 -> 16 | B17: 0062 | C17: 李俊廷 | D17: 車輛開發部 | E17: VD | F17: 陳冠文 | G17: 工程師 | H17: 沈大維 | R17: 管理部 | S17: AD | T17: 營業費用 | U17: =S17&R17 -> AD管理部 | V17: 設備 | W17: 115ADSE16 | X17: 設備 | Y17: 0 | Z17: =U17&V17 -> AD管理部設備 | AA17: =IF(OR(X17="旅費", X17="折舊及攤銷"), "無預算", IF(AND(ISNUMBER(Y17), Y17<>0), W17, "無預算")) -> 無預算 | AC17: 適用於封閉區域慢速自駕車之「通用型車頂整合設備包」設計 | AD17: 115BD005 | AE17: 陳冠文 | AG17: 雜項購置 | AI17: =AC16 -> 臺灣桃園國際機場第三航站區旅客運輸系統工程-建置車輛監控管理系統
A18: =ROW()-1 -> 17 | B18: 0065 | C18: 吳旭東 | D18: 管理部 | E18: AD | F18: 吳旭東 | G18: 協理 | H18: 沈大維 | R18: 管理部 | S18: AD | T18: 營業費用 | U18: =S18&R18 -> AD管理部 | V18: 雜項購置 | W18: 115ADSE17 | X18: =V18 -> 雜項購置 | Y18: -60000 | Z18: =U18&V18 -> AD管理部雜項購置 | AA18: =IF(OR(X18="旅費", X18="折舊及攤銷"), "無預算", IF(AND(ISNUMBER(Y18), Y18<>0), W18, "無預算")) -> 115ADSE17 | AC18: 國際拔尖潛力新創獎勵 | AD18: 115BD006 | AE18: 劉君怡 | AG18: 退休金 | AI18: 適用於封閉區域慢速自駕車之「通用型車頂整合設備包」設計
A19: =ROW()-1 -> 18 | B19: 0066 | C19: 劉又誠 | D19: 自動駕駛系統部 | E19: ADS | F19: 楊為任 | G19: 運動規劃演算法工程師 | H19: 沈大維 | R19: 管理部 | S19: AD | T19: 營業費用 | U19: =S19&R19 -> AD管理部 | V19: 退休金 | W19: 115ADSE18 | X19: =V19 -> 退休金 | Y19: -222168 | Z19: =U19&V19 -> AD管理部退休金 | AA19: =IF(OR(X19="旅費", X19="折舊及攤銷"), "無預算", IF(AND(ISNUMBER(Y19), Y19<>0), W19, "無預算")) -> 115ADSE18 | AC19: T0.9內部自研案 | AD19: 114GO001 | AE19: 李明潔 | AG19: 文具用品 | AI19: 國際拔尖潛力新創獎勵
A20: =ROW()-1 -> 19 | B20: 0067 | C20: 蔡廷法 | D20: 資料與雲端平台部 | E20: D&C | F20: 楊為任 | G20: 前端工程師 | H20: 沈大維 | R20: 管理部 | S20: AD | T20: 營業費用 | U20: =S20&R20 -> AD管理部 | V20: 文具用品 | W20: 115ADSE19 | X20: =V20 -> 文具用品 | Y20: -15000 | Z20: =U20&V20 -> AD管理部文具用品 | AA20: =IF(OR(X20="旅費", X20="折舊及攤銷"), "無預算", IF(AND(ISNUMBER(Y20), Y20<>0), W20, "無預算")) -> 115ADSE19 | AC20: Voyager T4產品開發案 | AD20: 114GO002 | AE20: 李明潔 | AG20: 水電費 | AI20: =AC19 -> T0.9內部自研案
A21: =ROW()-1 -> 20 | B21: 0069 | C21: 陳侑良 | D21: 自動駕駛系統部 | E21: ADS | F21: 楊為任 | G21: 資深定位融合演算法工程師 | H21: 沈大維 | R21: 管理部 | S21: AD | T21: 營業費用 | U21: =S21&R21 -> AD管理部 | V21: 水電費 | W21: 115ADSE20 | X21: =V21 -> 水電費 | Y21: -250000 | Z21: =U21&V21 -> AD管理部水電費 | AA21: =IF(OR(X21="旅費", X21="折舊及攤銷"), "無預算", IF(AND(ISNUMBER(Y21), Y21<>0), W21, "無預算")) -> 115ADSE20 | AC21: Voyager T14 產品開發案 | AD21: 115GO001 | AE21: 楊為任 | AG21: 捐贈 | AI21: =AC20 -> Voyager T4產品開發案
A22: =ROW()-1 -> 21 | B22: 0070 | C22: 劉君怡 | D22: 營業行銷部 | E22: S&M | F22: 陳維隆 | G22: 資深市場開發經理 | H22: 沈大維 | R22: 管理部 | S22: AD | T22: 營業費用 | U22: =S22&R22 -> AD管理部 | V22: 捐贈 | W22: 115ADSE21 | X22: =V22 -> 捐贈 | Y22: 0 | Z22: =U22&V22 -> AD管理部捐贈 | AA22: =IF(OR(X22="旅費", X22="折舊及攤銷"), "無預算", IF(AND(ISNUMBER(Y22), Y22<>0), W22, "無預算")) -> 無預算 | AG22: 銀行手續費 | AI22: =AC21 -> Voyager T14 產品開發案
A23: =ROW()-1 -> 22 | B23: 9974 | C23: 陳哲偉 | D23: 自動駕駛系統部 | E23: ADS | F23: 楊為任 | G23: 數據與驗證工程師 | H23: 沈大維 | R23: 管理部 | S23: AD | T23: 營業費用 | U23: =S23&R23 -> AD管理部 | V23: 銀行手續費 | W23: 115ADSE22 | X23: =V23 -> 銀行手續費 | Y23: -26000 | Z23: =U23&V23 -> AD管理部銀行手續費 | AA23: =IF(OR(X23="旅費", X23="折舊及攤銷"), "無預算", IF(AND(ISNUMBER(Y23), Y23<>0), W23, "無預算")) -> 115ADSE22 | AG23: 其他費用
A24: =ROW()-1 -> 23 | B24: 0071 | C24: 羅曉惠 | D24: 管理部 | E24: AD | F24: 吳旭東 | G24: 主辦財務會計 | H24: 沈大維 | R24: 管理部 | S24: AD | T24: 營業費用 | U24: =S24&R24 -> AD管理部 | V24: 其他費用 | W24: 115ADSE99 | X24: =V24 -> 其他費用 | Y24: -1160440 | Z24: =U24&V24 -> AD管理部其他費用 | AA24: =IF(OR(X24="旅費", X24="折舊及攤銷"), "無預算", IF(AND(ISNUMBER(Y24), Y24<>0), W24, "無預算")) -> 115ADSE99 | AG24: 非費用類項目
A25: =ROW()-1 -> 24 | B25: 0074 | C25: 卓欣葦 | D25: 管理部 | E25: AD | F25: 吳旭東 | G25: 資深人資專員 | H25: 沈大維 | R25: 管理部 | S25: AD | T25: 營業費用 | U25: =S25&R25 -> AD管理部 | V25: 非費用類項目 | W25: 115ADOTH | X25: =V25 -> 非費用類項目 | Y25: -12627719 | Z25: =U25&V25 -> AD管理部非費用類項目 | AA25: =IF(OR(X25="旅費", X25="折舊及攤銷"), "無預算", IF(AND(ISNUMBER(Y25), Y25<>0), W25, "無預算")) -> 115ADOTH | AG25: -----專案-----
A26: =ROW()-1 -> 25 | B26: 0075 | C26: 汪怡伶 | D26: 管理部 | E26: AD | F26: 吳旭東 | G26: 行政總務專員 | H26: 沈大維 | R26: 自動駕駛系統部 | S26: ADS | T26: 營業費用 | U26: =S26&R26 -> ADS自動駕駛系統部 | V26: 人事費 | W26: 115ADSSE01 | X26: 人事費(薪資、各項獎金) | Y26: -20842383 | Z26: =U26&V26 -> ADS自動駕駛系統部人事費 | AA26: =IF(OR(X26="旅費", X26="折舊及攤銷"), "無預算", IF(AND(ISNUMBER(Y26), Y26<>0), W26, "無預算")) -> 115ADSSE01 | AG26: *臨時人力
A27: =ROW()-1 -> 26 | B27: 0076 | C27: 陳奕儒 | D27: 自動駕駛系統部 | E27: ADS | F27: 楊為任 | G27: 規劃與控制演算法工程師 | H27: 沈大維 | R27: 自動駕駛系統部 | S27: ADS | T27: 營業費用 | U27: =S27&R27 -> ADS自動駕駛系統部 | V27: 租金支出 | W27: 115ADSSE02 | X27: 租金支出 | Y27: -559600 | Z27: =U27&V27 -> ADS自動駕駛系統部租金支出 | AA27: =IF(OR(X27="旅費", X27="折舊及攤銷"), "無預算", IF(AND(ISNUMBER(Y27), Y27<>0), W27, "無預算")) -> 115ADSSE02 | AG27: *材料
A28: =ROW()-1 -> 27 | B28: 0077 | C28: 陳劭穎 | D28: 自動駕駛系統部 | E28: ADS | F28: 楊為任 | G28: 感知演算法工程師 | H28: 沈大維 | R28: 自動駕駛系統部 | S28: ADS | T28: 營業費用 | U28: =S28&R28 -> ADS自動駕駛系統部 | V28: 旅費 | W28: 115ADSSE03 | X28: 旅費 | Y28: -300000 | Z28: =U28&V28 -> ADS自動駕駛系統部旅費 | AA28: =IF(OR(X28="旅費", X28="折舊及攤銷"), "無預算", IF(AND(ISNUMBER(Y28), Y28<>0), W28, "無預算")) -> 無預算 | AG28: *設備
A29: =ROW()-1 -> 28 | B29: 0078 | C29: 林琦淵 | D29: 自動駕駛系統部 | E29: ADS | F29: 楊為任 | G29: 控制演算法工程師 | H29: 沈大維 | R29: 自動駕駛系統部 | S29: ADS | T29: 營業費用 | U29: =S29&R29 -> ADS自動駕駛系統部 | V29: 運費 | W29: 115ADSSE04 | X29: 運費 | Y29: 0 | Z29: =U29&V29 -> ADS自動駕駛系統部運費 | AA29: =IF(OR(X29="旅費", X29="折舊及攤銷"), "無預算", IF(AND(ISNUMBER(Y29), Y29<>0), W29, "無預算")) -> 無預算 | AG29: *雜項購置
A30: =ROW()-1 -> 29 | B30: 0079 | C30: 張芷瑀 | D30: 自動駕駛系統部 | E30: ADS | F30: 楊為任 | G30: 軟體工程師 | H30: 沈大維 | R30: 自動駕駛系統部 | S30: ADS | T30: 營業費用 | U30: =S30&R30 -> ADS自動駕駛系統部 | V30: 郵電費 | W30: 115ADSSE05 | X30: 郵電費 | Y30: -36000 | Z30: =U30&V30 -> ADS自動駕駛系統部郵電費 | AA30: =IF(OR(X30="旅費", X30="折舊及攤銷"), "無預算", IF(AND(ISNUMBER(Y30), Y30<>0), W30, "無預算")) -> 115ADSSE05 | AG30: *委外
A31: =ROW()-1 -> 30 | B31: 0080 | C31: 陳映汝 | D31: 總經理室 | E31: GO | F31: 沈大維 | G31: UI/UX設計師 | H31: 沈大維 | R31: 自動駕駛系統部 | S31: ADS | T31: 營業費用 | U31: =S31&R31 -> ADS自動駕駛系統部 | V31: 修繕費 | W31: 115ADSSE06 | X31: 修繕費 | Y31: -20000 | Z31: =U31&V31 -> ADS自動駕駛系統部修繕費 | AA31: =IF(OR(X31="旅費", X31="折舊及攤銷"), "無預算", IF(AND(ISNUMBER(Y31), Y31<>0), W31, "無預算")) -> 115ADSSE06 | AG31: *差旅
A32: =ROW()-1 -> 31 | B32: 0081 | C32: 李明潔 | D32: 產品部 | E32: PD | F32: 沈大維 | G32: 產品經理 | H32: 沈大維 | R32: 自動駕駛系統部 | S32: ADS | T32: 營業費用 | U32: =S32&R32 -> ADS自動駕駛系統部 | V32: 廣告費 | W32: 115ADSSE07 | X32: 廣告費 | Y32: 0 | Z32: =U32&V32 -> ADS自動駕駛系統部廣告費 | AA32: =IF(OR(X32="旅費", X32="折舊及攤銷"), "無預算", IF(AND(ISNUMBER(Y32), Y32<>0), W32, "無預算")) -> 無預算 | AG32: *運費
A33: =ROW()-1 -> 32 | B33: 0082 | C33: 陳禮佑 | D33: 資料與雲端平台部 | E33: D&C | F33: 楊為任 | G33: 後端工程師 | H33: 沈大維 | R33: 自動駕駛系統部 | S33: ADS | T33: 營業費用 | U33: =S33&R33 -> ADS自動駕駛系統部 | V33: 保險費 | W33: 115ADSSE08 | X33: 保險費 | Y33: -1675862 | Z33: =U33&V33 -> ADS自動駕駛系統部保險費 | AA33: =IF(OR(X33="旅費", X33="折舊及攤銷"), "無預算", IF(AND(ISNUMBER(Y33), Y33<>0), W33, "無預算")) -> 115ADSSE08 | AG33: *雜費
A34: =ROW()-1 -> 33 | B34: 0083 | C34: 林韋志 | D34: 車輛開發部 | E34: VD | F34: 陳冠文 | G34: 軟韌體工程師 | H34: 沈大維 | R34: 自動駕駛系統部 | S34: ADS | T34: 營業費用 | U34: =S34&R34 -> ADS自動駕駛系統部 | V34: 交際費 | W34: 115ADSSE09 | X34: 交際費 | Y34: -12000 | Z34: =U34&V34 -> ADS自動駕駛系統部交際費 | AA34: =IF(OR(X34="旅費", X34="折舊及攤銷"), "無預算", IF(AND(ISNUMBER(Y34), Y34<>0), W34, "無預算")) -> 115ADSSE09
A35: =ROW()-1 -> 34 | B35: 0084 | C35: 詹家榆 | D35: 董事長室 | E35: CO | F35: 陳維隆 | G35: 營運顧問 | H35: 沈大維 | R35: 自動駕駛系統部 | S35: ADS | T35: 營業費用 | U35: =S35&R35 -> ADS自動駕駛系統部 | V35: 折舊及攤銷 | W35: 115ADSSE10 | X35: 折舊及攤銷 | Y35: -608784 | Z35: =U35&V35 -> ADS自動駕駛系統部折舊及攤銷 | AA35: =IF(OR(X35="旅費", X35="折舊及攤銷"), "無預算", IF(AND(ISNUMBER(Y35), Y35<>0), W35, "無預算")) -> 無預算
A36: =ROW()-1 -> 35 | B36: 0085 | C36: 王婷筠 | D36: 營業行銷部 | E36: S&M | F36: 陳維隆 | G36: 資深行銷經理 | H36: 沈大維 | R36: 自動駕駛系統部 | S36: ADS | T36: 營業費用 | U36: =S36&R36 -> ADS自動駕駛系統部 | V36: 職工福利 | W36: 115ADSSE11 | X36: 職工福利 | Y36: -30000 | Z36: =U36&V36 -> ADS自動駕駛系統部職工福利 | AA36: =IF(OR(X36="旅費", X36="折舊及攤銷"), "無預算", IF(AND(ISNUMBER(Y36), Y36<>0), W36, "無預算")) -> 115ADSSE11
A37: =ROW()-1 -> 36 | B37: 0088 | C37: 黃奕凱 | D37: 自動駕駛系統部 | E37: ADS | F37: 楊為任 | G37: 軟體工程師 | H37: 沈大維 | R37: 自動駕駛系統部 | S37: ADS | T37: 營業費用 | U37: =S37&R37 -> ADS自動駕駛系統部 | V37: 訓練費 | W37: 115ADSSE12 | X37: 訓練費 | Y37: 0 | Z37: =U37&V37 -> ADS自動駕駛系統部訓練費 | AA37: =IF(OR(X37="旅費", X37="折舊及攤銷"), "無預算", IF(AND(ISNUMBER(Y37), Y37<>0), W37, "無預算")) -> 無預算
A38: =ROW()-1 -> 37 | B38: 0089 | C38: 楊庭瑋 | D38: 營業行銷部 | E38: S&M | F38: 陳維隆 | G38: 副理 | H38: 沈大維 | R38: 自動駕駛系統部 | S38: ADS | T38: 營業費用 | U38: =S38&R38 -> ADS自動駕駛系統部 | V38: 開發費 | W38: 115ADSSE13 | X38: =V38 -> 開發費 | Y38: 0 | Z38: =U38&V38 -> ADS自動駕駛系統部開發費 | AA38: =IF(OR(X38="旅費", X38="折舊及攤銷"), "無預算", IF(AND(ISNUMBER(Y38), Y38<>0), W38, "無預算")) -> 無預算
A39: =ROW()-1 -> 38 | B39: 0090 | C39: 顏榆欣 | D39: 營業行銷部 | E39: S&M | F39: 陳維隆 | G39: 專案經理 | H39: 沈大維 | R39: 自動駕駛系統部 | S39: ADS | T39: 營業費用 | U39: =S39&R39 -> ADS自動駕駛系統部 | V39: 勞務費 | W39: 115ADSSE14 | X39: 勞務費 | Y39: 0 | Z39: =U39&V39 -> ADS自動駕駛系統部勞務費 | AA39: =IF(OR(X39="旅費", X39="折舊及攤銷"), "無預算", IF(AND(ISNUMBER(Y39), Y39<>0), W39, "無預算")) -> 無預算
A40: =ROW()-1 -> 39 | B40: 0091 | C40: 李盈萱 | D40: 管理部 | E40: AD | F40: 吳旭東 | G40: 主辦財務會計 | H40: 沈大維 | R40: 自動駕駛系統部 | S40: ADS | T40: 營業費用 | U40: =S40&R40 -> ADS自動駕駛系統部 | V40: 交通費 | W40: 115ADSSE15 | X40: 交通費 | Y40: -24000 | Z40: =U40&V40 -> ADS自動駕駛系統部交通費 | AA40: =IF(OR(X40="旅費", X40="折舊及攤銷"), "無預算", IF(AND(ISNUMBER(Y40), Y40<>0), W40, "無預算")) -> 115ADSSE15
...

Sheet 1.請購單
A1: 20260709版
A2: 台灣智慧駕駛股份有限公司
A3: 請購申請單
A5: 請購日期： | C5: =NOW() -> 46212.465 | F5: 申請單位： | G5: =_xlfn.XLOOKUP(G6,link!B:B,link!E:E,"") -> AD | H5: =_xlfn.XLOOKUP(G6,link!B:B,link!D:D,"") -> 管理部
A6: 請購單號(註1)： | C6: CP115040669 | E6: A1 | F6: 申請人員工號： | G6: 0091 | H6: =_xlfn.XLOOKUP(G6,link!B:B,link!C:C,"查無此人") -> 李盈萱 | S6: 請選擇
F7: 預計需求天數： | G7: 30 | H7: =C5+G7 -> 46242.465 | L7: 表單內的雙線外框儲存格為填寫欄位 | S7: 是，請提供採購選手清單
S8: 否
A9: 項 次 | B9: 預算來源 | C9: 預算來源代號 | D9: 項目 | E9: 預算編號 | F9: 說明 (目標規格/服務內容) | H9: 數量 | I9: 預估費用 (新臺幣) | L9: 提醒: 「請款單號、申請人員工號、預算來源、需求天數、項目、說明、數量、預估費用」欄位裡皆需選填及手動key入。 ※金額欄位可以自行修改「儲存格格式」，可修改幣別及小數位數。
A10: 1 | C10: =IF(_xlfn.XLOOKUP(B10,link!AC:AC,link!AD:AD)=0,"",_xlfn.XLOOKUP(B10,link!AC:AC,link!AD:AD)) | E10: =IF(D10="","",_xlfn.XLOOKUP($C$10&$B$10&D10,link!Z:Z,link!AA:AA,"無預算"))
A11: 2 | C11: =IF(_xlfn.XLOOKUP(B11,link!AC:AC,link!AD:AD)=0,"",_xlfn.XLOOKUP(B11,link!AC:AC,link!AD:AD)) | E11: =IF(D11="","",_xlfn.XLOOKUP($C$11&$B$11&D11,link!Z:Z,link!AA:AA,"無預算"))
A12: 3 | C12: =IF(_xlfn.XLOOKUP(B12,link!AC:AC,link!AD:AD)=0,"",_xlfn.XLOOKUP(B12,link!AC:AC,link!AD:AD)) | E12: =IF(D12="","",_xlfn.XLOOKUP($C$12&$B$12&D12,link!Z:Z,link!AA:AA,"無預算"))
A13: 4 | C13: =IF(_xlfn.XLOOKUP(B13,link!AC:AC,link!AD:AD)=0,"",_xlfn.XLOOKUP(B13,link!AC:AC,link!AD:AD)) | E13: =IF(D13="","",_xlfn.XLOOKUP($C$13&$B$13&D13,link!Z:Z,link!AA:AA,"無預算"))
A14: 5 | C14: =IF(_xlfn.XLOOKUP(B14,link!AC:AC,link!AD:AD)=0,"",_xlfn.XLOOKUP(B14,link!AC:AC,link!AD:AD)) | E14: =IF(D14="","",_xlfn.XLOOKUP($C$14&$B$14&D14,link!Z:Z,link!AA:AA,"無預算"))
A15: 6 | C15: =IF(_xlfn.XLOOKUP(B15,link!AC:AC,link!AD:AD)=0,"",_xlfn.XLOOKUP(B15,link!AC:AC,link!AD:AD)) | E15: =IF(D15="","",_xlfn.XLOOKUP($C$15&$B$15&D15,link!Z:Z,link!AA:AA,"無預算"))
H16: 總計 | I16: =IF(SUM(I10:I15)-ROUNDDOWN(SUM(I10:I15),0)>0,TEXT(SUM(I10:I15),"#,##0.00"),TEXT(SUM(I10:I15),"#,##0")) -> 0
A17: 備 註
A18: 後續是否進行同廠商、同品項的第二次採購
A19: 請選擇
A20: 註1：需向財會單位取號，編碼原則為CP+民國年月5碼(數字)+流水號4碼，請購單、採購單、驗收單編號有對應關係。
A21: 注意事項
A22: 1. 請購項目如為非裝在車體上隨車出售，且未稅金額達80,000(含)以上，請購項目才能選「設備」，否則請選「材料」。
A23: 2. 請購、採購及驗收請款流程請確實按照公司採購流程進行，勿將所有文件同時送簽。
A24: 核決 | C24: 預算負責人 | F24: 申請單位主管 | G24: 申請人 | I24: 經辦
A25: =IF(AND(E25="沈大維",F25="沈大維",G25="沈大維"),"沈大維+陳維隆",IF(SUM(I10:I15)>=100000,"沈大維+陳維隆","沈大維")) -> #N/A | C25: =_xlfn.XLOOKUP(C12,link!AD:AD,link!AE:AE) -> #N/A | D25: =_xlfn.XLOOKUP(C11,link!AD:AD,link!AE:AE) -> #N/A | E25: =_xlfn.XLOOKUP(C10,link!AD:AD,link!AE:AE) -> #N/A | F25: =_xlfn.XLOOKUP(G6,link!B:B,link!F:F,"") -> 吳旭東 | G25: =H6 -> 李盈萱
C27: =_xlfn.XLOOKUP(C15,link!AD:AD,link!AE:AE) -> #N/A | D27: =_xlfn.XLOOKUP(C14,link!AD:AD,link!AE:AE) -> #N/A | E27: =_xlfn.XLOOKUP(C13,link!AD:AD,link!AE:AE) -> #N/A
A29: 簽核流程：申請人→申請單位主管→預算負責人→總經理核決(若金額超過新臺幣10萬則需再簽到董事長)。

Sheet 供應商資料
A1: 廠商名稱 | B1: 電話 | C1: Mail Address | D1: 聯絡人
A2: 中華電信 | B2: 02-2706-6918#6988 | C2: summer797731@gmail.com | D2: 王先生
A3: 遠傳 | B3: 02-2706-6918#6988 | C3: summer797731@gmail.com | D3: 王小姐
A4: 台灣大哥大 | B4: 02-2706-6918#6988 | C4: 123@gmail.com | D4: 王小姐
A5: 台灣之星 | B5: 02-2706-6918#6988 | C5: 123@gmail.com | D5: 王小姐

Sheet 2. 採購單
A1: ='1.請購單'!A1 -> 20260709版
A2: 台灣智慧駕駛股份有限公司
A3: 採購申請單
T4: 請選擇
A5: 採購日期： | C5: =NOW() -> 46212.465 | F5: 預計採購廠商*： | T5: 因採購品項為特殊產品、僅有一家供應商可提供，故不檢附其他廠商報價單
A6: 採購單號： | C6: ='1.請購單'!C6 -> CP115040669 | E6: B1 | F6: 付款方式*： | H6: 匯款 | T6: 客戶指定
A7: 需求單位： | C7: ='1.請購單'!G5&'1.請購單'!H5 -> AD管理部 | F7: 付款條件*： | H7: 月結30天 | T7: 第二次採購
A8: 需求人員工號： | C8: ='1.請購單'!G6&'1.請購單'!H6 -> 0091李盈萱 | F8: 預計需求/交貨天數*： | H8: 30 | I8: =C5+H8 -> 46242.465
A10: 項 次 | B10: 預算來源 | C10: 項目(註1) | D10: 預算編號 | E10: 說明 品牌,型號規格,名稱 | G10: 單位 | H10: 單價 (新臺幣含營業稅) | I10: 數量 | J10: 總價 (新臺幣含營業稅) | M10: 表單內的雙線外框儲存格為填寫欄位
A11: 1 | B11: ='1.請購單'!B10&" "&'1.請購單'!C10 | C11: =IF('1.請購單'!D10=0,"",'1.請購單'!D10) | D11: =IF('1.請購單'!E10="","",'1.請購單'!E10) | J11: =(IF(H11*I11=0,"",H11*I11))
A12: 2 | B12: ='1.請購單'!B11&" "&'1.請購單'!C11 | C12: =IF('1.請購單'!D11=0,"",'1.請購單'!D11) | D12: =IF('1.請購單'!E11="","",'1.請購單'!E11) | J12: =(IF(H12*I12=0,"",H12*I12)) | M12: 提醒: 「預計採購廠商、付款方式、付款條件、需求(交貨)天數、項目、說明、單位、單價、數量、總價、備註」欄位裡皆需選填及手動key入。 ※金額欄位可以自行修改「儲存格格式」，可修改幣別及小數位數。
A13: 3 | B13: ='1.請購單'!B12&" "&'1.請購單'!C12 | C13: =IF('1.請購單'!D12=0,"",'1.請購單'!D12) | D13: =IF('1.請購單'!E12="","",'1.請購單'!E12) | J13: =(IF(H13*I13=0,"",H13*I13))
A14: 4 | B14: ='1.請購單'!B13&" "&'1.請購單'!C13 | C14: =IF('1.請購單'!D13=0,"",'1.請購單'!D13) | D14: =IF('1.請購單'!E13="","",'1.請購單'!E13) | J14: =(IF(H14*I14=0,"",H14*I14))
A15: 5 | B15: ='1.請購單'!B14&" "&'1.請購單'!C14 | C15: =IF('1.請購單'!D14=0,"",'1.請購單'!D14) | D15: =IF('1.請購單'!E14="","",'1.請購單'!E14) | J15: =(IF(H15*I15=0,"",H15*I15))
A16: 6 | B16: ='1.請購單'!B15&" "&'1.請購單'!C15 | C16: =IF('1.請購單'!D15=0,"",'1.請購單'!D15) | D16: =IF('1.請購單'!E15="","",'1.請購單'!E15) | J16: =(IF(H16*I16=0,"",H16*I16))
A17: 附件：□報價單□合約□客供資料卡 | I17: 合計 | J17: =IF(SUM(J11:J16)-ROUNDDOWN(SUM(J11:J16),0)>0,TEXT(SUM(J11:J16),"#,##0.00"),TEXT(SUM(J11:J16),"#,##0")) -> 0
A18: V | B18: =IF(J17<=30000,"應檢附1家報價單",IF(J17>=100000,"應檢附3家報價單","應檢附2家報價單")) -> 應檢附3家報價單
A19: =IF(A18="V","X",IF(A18="請選擇","","V")) -> X | B19: 未檢附其他報價單原因： | F19: 請選擇
A20: 備註：
A21: 註1：預算編號及項目應與請購單之內容相同。
A22: 註2：本採購相關附加費用需同時填寫，如預估關稅、運費、保險費…等。
A23: 注意事項
A24: 1. 採購項目如為非裝在車體上隨車出售，且未稅金額達80,000(含)以上，採購項目才能選「設備」，否則請選「材料」。
A25: 2. 如為國內廠商以外幣進行報價及收付款，請確定交易金額是否需含本國營業稅5%及該交易憑證開立方式。
A26: 3. 如採購金額超過3萬以上，或經常性每年採購6次以上之供應商，需請對方填寫「供應商基本資料卡」，並請申請人確認。
A27: 4. 廠商報價單上的付款條件，需能對應到該費用申請單的期望付款日。
A28: 5. 國內廠商之報價單公司抬頭必需為「台灣智慧駕駛股份有限公司」，國外廠商之QUOTATION公司抬頭必需為「TURING DRIVE INC.」。
A29: 6. 請購、採購及驗收請款流程請確實按照公司採購流程進行，勿將所有文件同時送簽。
A30: 7.採購金額<NT30,000→報價單x1家，採購金額NT30,000~NT100,000→報價單x2家，採購金額≧NT100,000→報價單x3家。
A31: 核決 | C31: 預算負責人 | F31: 申請單位主管 | H31: 申請人 | J31: 經辦
A32: =IF(AND(E32="沈大維",F32="沈大維",H32="沈大維"),"沈大維+陳維隆",IF(SUM(J11:J16)>=100000,"沈大維+陳維隆","沈大維")) -> #N/A | C32: =_xlfn.XLOOKUP('1.請購單'!C12,link!AD:AD,link!AE:AE) -> #N/A | D32: =_xlfn.XLOOKUP('1.請購單'!C11,link!AD:AD,link!AE:AE) -> #N/A | E32: =_xlfn.XLOOKUP('1.請購單'!C10,link!AD:AD,link!AE:AE) -> #N/A | F32: ='1.請購單'!F25 -> 吳旭東 | H32: ='1.請購單'!H6 -> 李盈萱
C34: =_xlfn.XLOOKUP('1.請購單'!C15,link!AD:AD,link!AE:AE) -> #N/A | D34: =_xlfn.XLOOKUP('1.請購單'!C14,link!AD:AD,link!AE:AE) -> #N/A | E34: =_xlfn.XLOOKUP('1.請購單'!C13,link!AD:AD,link!AE:AE) -> #N/A
A36: 簽核流程：申請人→申請單位主管→預算負責人→總經理核決(若金額超過新台幣10萬則需再簽到董事長)。

Sheet 3. 驗收單
A1: ='1.請購單'!A1 -> 20260709版
A2: 台灣智慧駕駛股份有限公司
A3: 驗收單
A5: 驗收日期： | C5: =NOW() -> 46212.465 | E5: 承攬廠商： | G5: ='2. 採購單'!H5 -> 0
A6: 驗收單號： | C6: ='2. 採購單'!C6 -> CP115040669 | D6: C1 | E6: 申請單位： | G6: ='2. 採購單'!C7 -> AD管理部
E7: 申請人： | G7: ='2. 採購單'!C8 -> 0091李盈萱
A9: 項 次 | B9: 預算來源 | C9: 項目 | D9: 預算編號 | E9: 說明 品牌,型號規格,名稱 | F9: 數量 | G9: 驗 收 | I9: 備註 | J9: 財產編號(註1)
G10: Pass or Fail
A11: 1 | B11: ='2. 採購單'!B11 | C11: ='2. 採購單'!C11 | D11: ='2. 採購單'!D11 | E11: =IF('2. 採購單'!E11="","",'2. 採購單'!E11) | F11: =IF('2. 採購單'!I11="","",'2. 採購單'!I11) | L11: 表單內的雙線外框儲存格為填寫欄位
A12: 2 | B12: ='2. 採購單'!B12 | C12: ='2. 採購單'!C12 | D12: ='2. 採購單'!D12 | E12: =IF('2. 採購單'!E12="","",'2. 採購單'!E12) | F12: =IF('2. 採購單'!I12="","",'2. 採購單'!I12)
A13: 3 | B13: ='2. 採購單'!B13 | C13: ='2. 採購單'!C13 | D13: ='2. 採購單'!D13 | E13: =IF('2. 採購單'!E13="","",'2. 採購單'!E13) | F13: =IF('2. 採購單'!I13="","",'2. 採購單'!I13) | L13: 提醒: 「驗收」欄位裡需選填，通過=Pass; 不通過=Fail
A14: 4 | B14: ='2. 採購單'!B14 | C14: ='2. 採購單'!C14 | D14: ='2. 採購單'!D14 | E14: =IF('2. 採購單'!E14="","",'2. 採購單'!E14) | F14: =IF('2. 採購單'!I14="","",'2. 採購單'!I14)
A15: 5 | B15: ='2. 採購單'!B15 | C15: ='2. 採購單'!C15 | D15: ='2. 採購單'!D15 | E15: =IF('2. 採購單'!E15="","",'2. 採購單'!E15) | F15: =IF('2. 採購單'!I15="","",'2. 採購單'!I15)
A16: 6 | B16: ='2. 採購單'!B16 | C16: ='2. 採購單'!C16 | D16: ='2. 採購單'!D16 | E16: =IF('2. 採購單'!E16="","",'2. 採購單'!E16) | F16: =IF('2. 採購單'!I16="","",'2. 採購單'!I16)
A17: 驗收單據或說明：
A29: 註1：若設備未稅金額在NT$80,000(含)以上，且耐用年限達2年以上需列入固定資產(資本支出且需造冊管理)
A30: 若材料未稅金額在NT$10,000(含)以上，或耐用年限達2年以上需列入庫存管理(雜項購置、原物料件且須造冊管理)
A31: 註2：請款時需檢附簽核完畢之驗收單及驗收文件影本。
A32: 注意事項
A33: 1. 付款條件如需支付預付款，不需送驗收單，待到貨後實際驗收完成再進行驗收流程。
A34: 2. 如上項預付貨款發生驗收不通過之情事，需另行申請開立進貨折讓單向廠商申請退款。
A35: 驗收審核 | J35: 財產入帳
A36: 預算負責人 | E36: 申請單位主管 | F36: 申請人 | I36: 驗收人 | J36: 汪怡伶
A37: ='2. 採購單'!C32 -> #N/A | C37: ='2. 採購單'!D32 -> #N/A | D37: ='2. 採購單'!E32 -> #N/A | E37: ='2. 採購單'!F32 -> 吳旭東 | F37: ='2. 採購單'!H32 -> 李盈萱
A39: ='2. 採購單'!C34 -> #N/A | C39: ='2. 採購單'!D34 -> #N/A | D39: ='2. 採購單'!E34 -> #N/A
A41: 簽核流程：驗收人+申請人→申請單位主管→預算負責人→管理單位填寫財產編號造冊列管。

Sheet 4. 費用申請單
A1: ='1.請購單'!A1 -> 20260709版
A2: 台灣智慧駕駛股份有限公司
A3: 費用申請單
A5: 申請日期： | C5: =NOW() -> 46212.465 | E5: 申請單位： | G5: =_xlfn.XLOOKUP(G6,link!B:B,link!E:E,"") -> AD | H5: =_xlfn.XLOOKUP(G6,link!B:B,link!D:D,"") -> 管理部
E6: 申請人工號： | G6: 0091 | H6: =_xlfn.XLOOKUP(G6,link!B:B,link!C:C,"查無此人") -> 李盈萱
A8: 項次 | B8: 預算來源 | C8: 代號 | D8: 項目(註1) | E8: 預算代號 | F8: 內容或說明 品牌,型號規格,名稱 | I8: 金 額 (新臺幣)
A9: 1 | C9: =IF(_xlfn.XLOOKUP(B9,link!AC:AC,link!AD:AD)=0,"",_xlfn.XLOOKUP(B9,link!AC:AC,link!AD:AD)) | E9: =IF(D9="","",_xlfn.XLOOKUP($C$9&$B$9&D9,link!Z:Z,link!AA:AA,"無預算")) | L9: 表單內的雙線外框儲存格為填寫欄位
A10: 2 | C10: =IF(_xlfn.XLOOKUP(B10,link!AC:AC,link!AD:AD)=0,"",_xlfn.XLOOKUP(B10,link!AC:AC,link!AD:AD)) | E10: =IF(D10="","",_xlfn.XLOOKUP($C$10&$B$10&D10,link!Z:Z,link!AA:AA,"無預算"))
A11: 3 | C11: =IF(_xlfn.XLOOKUP(B11,link!AC:AC,link!AD:AD)=0,"",_xlfn.XLOOKUP(B11,link!AC:AC,link!AD:AD)) | E11: =IF(D11="","",_xlfn.XLOOKUP($C$11&$B$11&D11,link!Z:Z,link!AA:AA,"無預算")) | L11: 溫馨提醒: 「預計來源、申請人工號、項目、說明、金額、付款資訊」欄位裡皆需選填及手動key入。
A12: 4 | C12: =IF(_xlfn.XLOOKUP(B12,link!AC:AC,link!AD:AD)=0,"",_xlfn.XLOOKUP(B12,link!AC:AC,link!AD:AD)) | E12: =IF(D12="","",_xlfn.XLOOKUP($C$12&$B$12&D12,link!Z:Z,link!AA:AA,"無預算"))
A13: 5 | C13: =IF(_xlfn.XLOOKUP(B13,link!AC:AC,link!AD:AD)=0,"",_xlfn.XLOOKUP(B13,link!AC:AC,link!AD:AD)) | E13: =IF(D13="","",_xlfn.XLOOKUP($C$13&$B$13&D13,link!Z:Z,link!AA:AA,"無預算"))
A14: 6 | C14: =IF(_xlfn.XLOOKUP(B14,link!AC:AC,link!AD:AD)=0,"",_xlfn.XLOOKUP(B14,link!AC:AC,link!AD:AD)) | E14: =IF(D14="","",_xlfn.XLOOKUP($C$14&$B$14&D14,link!Z:Z,link!AA:AA,"無預算"))
A15: 總金額 | I15: =IF(SUM(I9:I14)-ROUNDDOWN(SUM(I9:I14),0)>0,TEXT(SUM(I9:I14),"#,##0.00"),TEXT(SUM(I9:I14),"#,##0")) -> 0
A16: ………………………………… 付 款 資 訊 …………………………………
B17: 付款對象： | C17: 外部廠商 | E17: 銀行名稱：
B18: 付款方式： | C18: 匯款 | E18: 銀行戶名：
B19: 期望付款日： | E19: 銀行帳號：
B20: ※請確實填寫期望付款日以利安排匯款，若未填寫，付款條件將以月結30天計算
A21: 備註:
A26: 注意事項
A27: 1. 發票或收據買受人需為台灣智慧駕駛股份有限公司、統一編號為50773141，國外INVOICE或RECEIPT買受人需為TURING DRIVE INC.。
A28: 2. 賣方名稱、統一編號、地址、電話應清晰可辦認；發票或收據若有書寫錯誤、塗改或模糊不清者均無效，需請賣方重新開立。
A29: 3. 數量乘以單價應等於總金額並應與中文大寫金額相同；發票和免用統一發票收據的總計中文大寫處，請寫”零壹貳參肆伍陸柒捌玖”。
A30: 4. 各式憑證請另外拿紙黏貼並附於費用申請單之後，憑證重要資訊請勿覆蓋。
A31: 5. 費用申請單每項填寫單一憑證資訊，並於原始憑證註記項次以便查詢，切勿合併填寫。
A32: 6. 交際費請款必需寫上宴請對象。
A33: 7.申請之費用如有使用期間（如：軟體帳號使用期間及訂閱期間…等），請務必註明。
A34: 核 決 | C34: 預算負責人 | F34: 申請單位主管 | H34: 申請人 | I34: 經辦
A35: =IF(AND(E35="沈大維",F35="沈大維",H35="沈大維"),"沈大維+陳維隆",IF(SUM(I9:I14)>=100000,"沈大維+陳維隆","沈大維")) -> #N/A | C35: =_xlfn.XLOOKUP(C11,link!AD:AD,link!AE:AE) -> #N/A | D35: =_xlfn.XLOOKUP(C10,link!AD:AD,link!AE:AE) -> #N/A | E35: =_xlfn.XLOOKUP(C9,link!AD:AD,link!AE:AE) -> #N/A | F35: =_xlfn.XLOOKUP(G6,link!B:B,link!F:F,"") -> 吳旭東 | H35: =H6 -> 李盈萱
C37: =_xlfn.XLOOKUP(C14,link!AD:AD,link!AE:AE) -> #N/A | D37: =_xlfn.XLOOKUP(C13,link!AD:AD,link!AE:AE) -> #N/A | E37: =_xlfn.XLOOKUP(C12,link!AD:AD,link!AE:AE) -> #N/A
A39: 簽核流程：申請人→申請單位主管→預算負責人→總經理核決(若金額超過新台幣10萬則需再簽到董事長)。

Sheet 5.採購選手清單
A1: ='1.請購單'!A1 -> 20260709版
A2: 台灣智慧駕駛股份有限公司
A3: 採購選手清單
A5: 申請日期： | C5: =NOW() -> 46212.465 | E5: 申請單位： | F5: =_xlfn.XLOOKUP(F6,link!B:B,link!E:E,"") -> S&M | G5: =_xlfn.XLOOKUP(F6,link!B:B,link!D:D,"") -> 營業行銷部
B6: 期望到貨日： | C6: 45713 | E6: 申請人員工號： | F6: 0085 | G6: =_xlfn.XLOOKUP(F6,link!B:B,link!C:C,"查無此人") -> 王婷筠
A8: 項 次 | B8: 廠商 | C8: 品牌 | D8: 型號規格 | E8: 品名 | F8: 數量 | G8: 單位 | H8: 備註
A9: 1
A10: 2
A11: 3
A12: 4
A13: 5
A14: 6
A15: 7
A16: 8
A18: 廠商名稱 | C18: 電話 | D18: Mail Address | F18: 聯絡人
E22: 需求單位簽名：

Sheet 6.客供資料卡
A1: ='1.請購單'!A1 -> 20260709版
A2: 台灣智慧駕駛股份有限公司
A3: 客戶/供應商 資料卡
A5: 填表日期： | C5: =TODAY() -> 46212
A6: 公司名稱 | G6: 公司所屬國籍
A7: 公司簡稱 | G7: 客戶/供應商 代號
A8: 公司註冊編號
A9: 登記地址
A10: 通訊地址
A11: 公司電話
A12: 聯絡人姓名 | G12: 聯絡人單位
A13: 聯絡人電話 | G13: 聯絡人手機
A14: E-mail
A15: 往來 銀行 | B15: 銀行名稱 | E15: 分行 | F15: 帳號 | I15: 帳戶名稱 | J15: 交易幣別
A17: 備註
A18: ※請盡量檢附銀行帳號資訊。
A19: 銀行帳號黏貼處
A20: 以上資料均已向客戶或供應商確認屬實。 | H20: 申請人：
